Workbook

Sheet Jordan's sheet
A1: SN | B1: Station | C1: GPN | D1: WO | E1: Prod | G1: pack
A2: FWI2528-16951 | B2: AST ORT | C2: 1154427 | D2: 000007012469 | E2: ACON | F2: =IF(ISNUMBER(MATCH(A2, 'Larry''s sheet old'!$A:$A, 0)), "", "✅ Only in Sheet1") | G2: =IF(COUNTIF('Already Pack'!$A:$A, A2)>0, "pack", "")
A3: FWI2451-00124 | B3: XENA ORT | C3: 1176687 | D3: 000007008329 | E3: XCON | F3: =IF(ISNUMBER(MATCH(A3, 'Larry''s sheet old'!$A:$A, 0)), "", "✅ Only in Sheet1") -> ✅ Only in Sheet1 | G3: =IF(COUNTIF('Already Pack'!$A:$A, A3)>0, "pack", "")
A4: FWI2524-19526 | B4: AST ORT | C4: 1182051 | D4: 000007011761 | E4: GLP | F4: =IF(ISNUMBER(MATCH(A4, 'Larry''s sheet old'!$A:$A, 0)), "", "✅ Only in Sheet1") | G4: =IF(COUNTIF('Already Pack'!$A:$A, A4)>0, "pack", "")
A5: FWI2540-04321 | B5: AST ORT | C5: 1207949 | D5: 000007014794 | E5: TURI | F5: =IF(ISNUMBER(MATCH(A5, 'Larry''s sheet old'!$A:$A, 0)), "", "✅ Only in Sheet1") -> ✅ Only in Sheet1 | G5: =IF(COUNTIF('Already Pack'!$A:$A, A5)>0, "pack", "")
A6: FWI2536-01389 | B6: AST ORT | C6: 1158442 | D6: 000007013928 | E6: ACON | F6: =IF(ISNUMBER(MATCH(A6, 'Larry''s sheet old'!$A:$A, 0)), "", "✅ Only in Sheet1") -> ✅ Only in Sheet1 | G6: =IF(COUNTIF('Already Pack'!$A:$A, A6)>0, "pack", "") -> pack
A7: FWI2534-00290 | B7: Athena ORT | C7: 1176304 | D7: 000007013473 | E7: ATHN | F7: =IF(ISNUMBER(MATCH(A7, 'Larry''s sheet old'!$A:$A, 0)), "", "✅ Only in Sheet1") -> ✅ Only in Sheet1 | G7: =IF(COUNTIF('Already Pack'!$A:$A, A7)>0, "pack", "")
A8: FWI2530-05359 | B8: AST ORT | C8: 1168109 | D8: 000007012771 | E8: ACON | F8: =IF(ISNUMBER(MATCH(A8, 'Larry''s sheet old'!$A:$A, 0)), "", "✅ Only in Sheet1") -> ✅ Only in Sheet1 | G8: =IF(COUNTIF('Already Pack'!$A:$A, A8)>0, "pack", "") -> pack
A9: FWI2533-00342 | B9: Athena ORT | C9: 1176304 | D9: 000007013240 | E9: ATHN | F9: =IF(ISNUMBER(MATCH(A9, 'Larry''s sheet old'!$A:$A, 0)), "", "✅ Only in Sheet1") | G9: =IF(COUNTIF('Already Pack'!$A:$A, A9)>0, "pack", "")
A10: FWI2539-10798 | B10: AST ORT | C10: 1207953 | D10: 000007014797 | E10: TURI | F10: =IF(ISNUMBER(MATCH(A10, 'Larry''s sheet old'!$A:$A, 0)), "", "✅ Only in Sheet1") | G10: =IF(COUNTIF('Already Pack'!$A:$A, A10)>0, "pack", "")
A11: FWI2529-14089 | B11: AST ORT | C11: 1182051 | D11: 000007012627 | E11: GLP | F11: =IF(ISNUMBER(MATCH(A11, 'Larry''s sheet old'!$A:$A, 0)), "", "✅ Only in Sheet1") | G11: =IF(COUNTIF('Already Pack'!$A:$A, A11)>0, "pack", "") -> pack
A12: FWI2529-20793 | B12: AST ORT | C12: 1154427 | D12: 000007012705 | E12: ACON | F12: =IF(ISNUMBER(MATCH(A12, 'Larry''s sheet old'!$A:$A, 0)), "", "✅ Only in Sheet1") | G12: =IF(COUNTIF('Already Pack'!$A:$A, A12)>0, "pack", "")
A13: FWI2530-04796 | B13: AST ORT | C13: 1182051 | D13: 000007012770 | E13: GLP | F13: =IF(ISNUMBER(MATCH(A13, 'Larry''s sheet old'!$A:$A, 0)), "", "✅ Only in Sheet1") | G13: =IF(COUNTIF('Already Pack'!$A:$A, A13)>0, "pack", "") -> pack
... A330: FWI2536-03646 | B330: Athena ORT | C330: 1176304 | D330: 000007013939 | E330: ATHN | F330: =IF(ISNUMBER(MATCH(A330, 'Larry''s sheet old'!$A:$A, 0)), "", "✅ Only in Sheet1") | G330: =IF(COUNTIF('Already Pack'!$A:$A, A330)>0, "pack", "")

Sheet Already Pack
A1: FWI2536-01389 | B1: PASSED
A2: FWI2530-05359 | B2: PASSED
A3: FWI2529-14089 | B3: PASSED
A4: FWI2530-04796 | B4: PASSED
A5: FWI2533-01632 | B5: PASSED
A6: FWI2536-01251 | B6: PASSED
A7: FWI2534-12268 | B7: PASSED
A8: FWI2530-10517 | B8: PASSED
A9: FWI2535-00120 | B9: PASSED
A10: FWI2535-10558 | B10: PASSED
A11: FWI2536-01428 | B11: PASSED
A12: FWI2536-00356 | B12: PASSED
... A35: FWI2541-10034 | B35: PASSED

Sheet Jordan's sheet no pack
A1: SN | B1: Station | C1: GPN | D1: WO | E1: Prod
A2: FWI2528-16951 | B2: AST ORT | C2: 1154427 | D2: 000007012469 | E2: ACON
A3: FWI2451-00124 | B3: XENA ORT | C3: 1176687 | D3: 000007008329 | E3: XCON
A4: FWI2524-19526 | B4: AST ORT | C4: 1182051 | D4: 000007011761 | E4: GLP
A5: FWI2540-04321 | B5: AST ORT | C5: 1207949 | D5: 000007014794 | E5: TURI
A6: FWI2534-00290 | B6: Athena ORT | C6: 1176304 | D6: 000007013473 | E6: ATHN
A7: FWI2533-00342 | B7: Athena ORT | C7: 1176304 | D7: 000007013240 | E7: ATHN
A8: FWI2539-10798 | B8: AST ORT | C8: 1207953 | D8: 000007014797 | E8: TURI
A9: FWI2529-20793 | B9: AST ORT | C9: 1154427 | D9: 000007012705 | E9: ACON
A10: FWI2530-13313 | B10: Athena ORT | C10: 1178139 | D10: 000007012863 | E10: ATHN
A11: FWI2536-03302 | B11: Athena ORT | C11: 1176304 | D11: 000007013939 | E11: ATHN
A12: FWI2529-19116 | B12: Athena ORT | C12: 1176304 | D12: 000007012657 | E12: ATHN
... A295: FWI2536-03646 | B295: Athena ORT | C295: 1176304 | D295: 000007013939 | E295: ATHN

Sheet Larry's sheet new
A1: SN | B1: Prod
A2: FWI2537-12128 | B2: GLP
A3: FWI2537-12121 | B3: GLP
A4: FWI2537-12089 | B4: GLP
A5: FWI2537-12049 | B5: GLP
A6: FWI2532-05651 | B6: GLP
A7: FWI2528-13950 | B7: GLP
A8: FWI2537-12078 | B8: GLP
A9: FWI2534-06197 | B9: GA
A10: FWI2536-10332 | B10: GA
A11: FWI2539-11031 | B11: GA
A12: FWI2536-01574 | B12: GA
... A203: FWI2535-10177 | B203: Athena

Sheet New discrepancy
A1: SN | B1: Prod
A2: FWI2451-00124 | B2: XCON | C2: =IF(COUNTIF($I:$I,A2)>0,"In I","Not in I") -> Not in I | I2: FWI2530-05359 | J2: pack
A3: FWI2524-19526 | B3: GLP | C3: =IF(COUNTIF($I:$I,A3)>0,"In I","Not in I") -> Not in I | I3: FWI2534-00290 | J3: Repair
A4: FWI2540-04321 | B4: TURI | C4: =IF(COUNTIF($I:$I,A4)>0,"In I","Not in I") -> In I | I4: FWI2534-15102
A5: FWI2534-00290 | B5: ATHN | C5: =IF(COUNTIF($I:$I,A5)>0,"In I","Not in I") -> In I | I5: FWI2534-15134 | J5: Repair
A6: FWI2529-20793 | B6: ACON | C6: =IF(COUNTIF($I:$I,A6)>0,"In I","Not in I") -> Not in I | I6: FWI2535-09824
A7: FWI2530-13629 | B7: ATHN | C7: =IF(COUNTIF($I:$I,A7)>0,"In I","Not in I") -> Not in I | I7: FWI2536-01251 | J7: pack
A8: FWI2533-06803 | B8: ATHN | C8: =IF(COUNTIF($I:$I,A8)>0,"In I","Not in I") -> Not in I | I8: FWI2536-01389 | J8: pack
A9: FWI2531-13801 | B9: ATHN | C9: =IF(COUNTIF($I:$I,A9)>0,"In I","Not in I") -> Not in I | I9: FWI2536-01408 | J9: pack
A10: FWI2534-15335 | B10: ATHN | C10: =IF(COUNTIF($I:$I,A10)>0,"In I","Not in I") -> Not in I | I10: FWI2536-01428 | J10: pack
A11: FWI2533-06775 | B11: ATHN | C11: =IF(COUNTIF($I:$I,A11)>0,"In I","Not in I") -> Not in I | I11: FWI2536-01541 | J11: pack
A12: FWI2537-12411 | B12: ATHN | C12: =IF(COUNTIF($I:$I,A12)>0,"In I","Not in I") -> Not in I | I12: FWI2536-10356 | J12: pack
A13: FWI2534-14892 | B13: ATHN | C13: =IF(COUNTIF($I:$I,A13)>0,"In I","Not in I") -> Not in I | I13: FWI2536-10717 | J13: pack
A14: FWI2536-03795 | B14: ATHN | C14: =IF(COUNTIF($I:$I,A14)>0,"In I","Not in I") -> Not in I | I14: FWI2536-11054 | J14: pack
A15: FWI2536-03239 | B15: ATHN | C15: =IF(COUNTIF($I:$I,A15)>0,"In I","Not in I") -> Not in I | I15: FWI2537-01430 | J15: v
A16: FWI2537-12213 | B16: ATHN | C16: =IF(COUNTIF($I:$I,A16)>0,"In I","Not in I") -> Not in I | I16: FWI2537-12514
A17: FWI2535-11022 | B17: ATHN | C17: =IF(COUNTIF($I:$I,A17)>0,"In I","Not in I") -> Not in I | I17: FWI2538-07772
A18: FWI2535-00124 | B18: TURI | C18: =IF(COUNTIF($I:$I,A18)>0,"In I","Not in I") -> Not in I | I18: FWI2539-05455
A19: FWI2535-10975 | B19: ATHN | C19: =IF(COUNTIF($I:$I,A19)>0,"In I","Not in I") -> Not in I | I19: FWI2539-05489
A20: FWI2534-00666 | B20: ATHN | C20: =IF(COUNTIF($I:$I,A20)>0,"In I","Not in I") -> Not in I | I20: FWI2539-05971
A21: FWI2534-00570 | B21: ATHN | C21: =IF(COUNTIF($I:$I,A21)>0,"In I","Not in I") -> Not in I | I21: FWI2539-05992
A22: FWI2536-03432 | B22: ATHN | C22: =IF(COUNTIF($I:$I,A22)>0,"In I","Not in I") -> Not in I | I22: FWI2539-06092
A23: FWI2530-13669 | B23: ATHN | C23: =IF(COUNTIF($I:$I,A23)>0,"In I","Not in I") -> Not in I | I23: FWI2539-06121
A24: FWI2530-04026 | B24: ATHN | C24: =IF(COUNTIF($I:$I,A24)>0,"In I","Not in I") -> Not in I | I24: FWI2539-06134
A25: FWI2539-09317 | B25: ATHN | C25: =IF(COUNTIF($I:$I,A25)>0,"In I","Not in I") -> In I | I25: FWI2539-06150
A26: FWI2537-12214 | B26: ATHN | C26: =IF(COUNTIF($I:$I,A26)>0,"In I","Not in I") -> Not in I | I26: FWI2539-06413
A27: FWI2536-00042 | B27: TURI | C27: =IF(COUNTIF($I:$I,A27)>0,"In I","Not in I") -> Not in I | I27: FWI2539-09242
... A40: FWI2536-11662 | B40: ACON | C40: =IF(COUNTIF($I:$I,A40)>0,"In I","Not in I") -> Not in I | I40: FWI2540-07734
A41: FWI2536-03513 | B41: ATHN | C41: =IF(COUNTIF($I:$I,A41)>0,"In I","Not in I") -> Not in I
A42: FWI2528-17975 | B42: ATHN | C42: =IF(COUNTIF($I:$I,A42)>0,"In I","Not in I") -> Not in I
A43: FWI2539-09242 | B43: ATHN | C43: =IF(COUNTIF($I:$I,A43)>0,"In I","Not in I") -> In I
A44: FWI2537-12423 | B44: ATHN | C44: =IF(COUNTIF($I:$I,A44)>0,"In I","Not in I") -> Not in I
A45: FWI2535-00276 | B45: TURI | C45: =IF(COUNTIF($I:$I,A45)>0,"In I","Not in I") -> Not in I
A46: FWI2539-06092 | B46: ATHN | C46: =IF(COUNTIF($I:$I,A46)>0,"In I","Not in I") -> In I
A47: FWI2536-03754 | B47: ATHN | C47: =IF(COUNTIF($I:$I,A47)>0,"In I","Not in I") -> Not in I
A48: FWI2530-03961 | B48: ATHN | C48: =IF(COUNTIF($I:$I,A48)>0,"In I","Not in I") -> Not in I
A49: FWI2538-07772 | B49: ATHN | C49: =IF(COUNTIF($I:$I,A49)>0,"In I","Not in I") -> In I
A50: FWI2540-04233 | B50: TURI | C50: =IF(COUNTIF($I:$I,A50)>0,"In I","Not in I") -> In I
A51: FWI2530-13654 | B51: ATHN | C51: =IF(COUNTIF($I:$I,A51)>0,"In I","Not in I") -> Not in I
A52: FWI2537-12414 | B52: ATHN | C52: =IF(COUNTIF($I:$I,A52)>0,"In I","Not in I") -> Not in I
...

Sheet Sheet10
A1: FWI2529-20793 | B1: ACON | C1: Not in I
A2: FWI2536-11662 | B2: ACON | C2: Not in I
A3: FWI2539-10922 | B3: ACON | C3: Not in I
A4: FWI2539-10243 | B4: ACON | C4: Not in I
A5: FWI2530-13629 | B5: ATHN | C5: Not in I
A6: FWI2533-06803 | B6: ATHN | C6: Not in I
A7: FWI2531-13801 | B7: ATHN | C7: Not in I
A8: FWI2534-15335 | B8: ATHN | C8: Not in I
A9: FWI2533-06775 | B9: ATHN | C9: Not in I
A10: FWI2537-12411 | B10: ATHN | C10: Not in I
A11: FWI2534-14892 | B11: ATHN | C11: Not in I
A12: FWI2536-03795 | B12: ATHN | C12: Not in I
... A71: FWI2451-00124 | B71: XCON | C71: Not in I

Sheet Larry's sheet old
A1: SN | B1: Prod
A2: FWI2535-10483 | B2: GA
A3: FWI2535-00066 | B3: GA | C3: =1+1 -> 2
A4: FWI2536-11057 | B4: GA
A5: FWI2535-10558 | B5: GA
A6: FWI2529-20793 | B6: GA
A7: FWI2536-10280 | B7: GA
A8: FWI2536-11662 | B8: GA
A9: FWI2536-10495 | B9: GA
A10: FWI2536-10876 | B10: GA
A11: FWI2536-01574 | B11: GA
A12: FWI2535-10487 | B12: GA
A13: FWI2524-19526 | B13: GA
A14: FWI2536-11662 | B14: GA
A15: FWI2536-10332 | B15: GA
... A249: FWI2536-00066 | B249: GLP

Sheet sheet3
A1: SN | B1: Station | C1: GPN | D1: WO | E1: Prod
A2: FWI2451-00124 | B2: XENA ORT | C2: 1176687 | D2: 000007008329 | E2: XCON | F2: =IF(COUNTIF($I:$I,A2)>0,"In I","Not in I") -> Not in I | I2: FWI2530-05359 | J2: pack
A3: FWI2530-05359 | B3: AST ORT | C3: 1168109 | D3: 000007012771 | E3: ACON | F3: =IF(COUNTIF($I:$I,A3)>0,"In I","Not in I") -> In I | I3: FWI2534-00290 | J3: Repair
A4: FWI2536-01251 | B4: AST ORT | C4: 1158442 | D4: 000007013928 | E4: ACON | F4: =IF(COUNTIF($I:$I,A4)>0,"In I","Not in I") -> In I | I4: FWI2534-15102
A5: FWI2536-01389 | B5: AST ORT | C5: 1158442 | D5: 000007013928 | E5: ACON | F5: =IF(COUNTIF($I:$I,A5)>0,"In I","Not in I") -> In I | I5: FWI2534-15134 | J5: Repair
A6: FWI2536-01408 | B6: AST ORT | C6: 1158442 | D6: 000007013928 | E6: ACON | F6: =IF(COUNTIF($I:$I,A6)>0,"In I","Not in I") -> In I | I6: FWI2535-09824
A7: FWI2536-01428 | B7: AST ORT | C7: 1158442 | D7: 000007013928 | E7: ACON | F7: =IF(COUNTIF($I:$I,A7)>0,"In I","Not in I") -> In I | I7: FWI2536-01251 | J7: pack
A8: FWI2536-01541 | B8: AST ORT | C8: 1158442 | D8: 000007013928 | E8: ACON | F8: =IF(COUNTIF($I:$I,A8)>0,"In I","Not in I") -> In I | I8: FWI2536-01389 | J8: pack
A9: FWI2536-10356 | B9: AST ORT | C9: 1158445 | D9: 000007013978 | E9: ACON | F9: =IF(COUNTIF($I:$I,A9)>0,"In I","Not in I") -> In I | I9: FWI2536-01408 | J9: pack
A10: FWI2536-10717 | B10: AST ORT | C10: 1158445 | D10: 000007013978 | E10: ACON | F10: =IF(COUNTIF($I:$I,A10)>0,"In I","Not in I") -> In I | I10: FWI2536-01428 | J10: pack
A11: FWI2536-11054 | B11: AST ORT | C11: 1158445 | D11: 000007013978 | E11: ACON | F11: =IF(COUNTIF($I:$I,A11)>0,"In I","Not in I") -> In I | I11: FWI2536-01541 | J11: pack
A12: FWI2531-13801 | B12: Athena ORT | C12: 1176304 | D12: 000007013067 | E12: ATHN | F12: =IF(COUNTIF($I:$I,A12)>0,"In I","Not in I") -> Not in I | I12: FWI2536-10356 | J12: pack
A13: FWI2534-00290 | B13: Athena ORT | C13: 1176304 | D13: 000007013473 | E13: ATHN | F13: =IF(COUNTIF($I:$I,A13)>0,"In I","Not in I") -> In I | I13: FWI2536-10717 | J13: pack
A14: FWI2534-15102 | B14: Athena ORT | C14: 1178139 | D14: 000007013550 | E14: ATHN | F14: =IF(COUNTIF($I:$I,A14)>0,"In I","Not in I") -> In I | I14: FWI2536-11054 | J14: pack
A15: FWI2534-15134 | B15: Athena ORT | C15: 1178139 | D15: 000007013550 | E15: ATHN | F15: =IF(COUNTIF($I:$I,A15)>0,"In I","Not in I") -> In I | I15: FWI2537-01430 | J15: v
A16: FWI2535-09824 | B16: Athena ORT | C16: 1176304 | D16: 000007013769 | E16: ATHN | F16: =IF(COUNTIF($I:$I,A16)>0,"In I","Not in I") -> In I | I16: FWI2537-12514
A17: FWI2535-10893 | B17: Athena ORT | C17: 1176304 | D17: 000007013817 | E17: ATHN | F17: =IF(COUNTIF($I:$I,A17)>0,"In I","Not in I") -> Not in I | I17: FWI2538-07772
A18: FWI2537-01430 | B18: Athena ORT | C18: 1176304 | D18: 000007014100 | E18: ATHN | F18: =IF(COUNTIF($I:$I,A18)>0,"In I","Not in I") -> In I | I18: FWI2539-05455
A19: FWI2537-12514 | B19: Athena ORT | C19: 1178139 | D19: 000007014267 | E19: ATHN | F19: =IF(COUNTIF($I:$I,A19)>0,"In I","Not in I") -> In I | I19: FWI2539-05489
A20: FWI2537-12653 | B20: Athena ORT | C20: 1178139 | D20: 000007014267 | E20: ATHN | F20: =IF(COUNTIF($I:$I,A20)>0,"In I","Not in I") -> Not in I | I20: FWI2539-05971
A21: FWI2537-12677 | B21: Athena ORT | C21: 1178139 | D21: 000007014267 | E21: ATHN | F21: =IF(COUNTIF($I:$I,A21)>0,"In I","Not in I") -> Not in I | I21: FWI2539-05992
A22: FWI2537-12707 | B22: Athena ORT | C22: 1178139 | D22: 000007014267 | E22: ATHN | F22: =IF(COUNTIF($I:$I,A22)>0,"In I","Not in I") -> Not in I | I22: FWI2539-06092
A23: FWI2537-12732 | B23: Athena ORT | C23: 1178139 | D23: 000007014267 | E23: ATHN | F23: =IF(COUNTIF($I:$I,A23)>0,"In I","Not in I") -> Not in I | I23: FWI2539-06121
A24: FWI2538-07772 | B24: Athena ORT | C24: 1176304 | D24: 000007014391 | E24: ATHN | F24: =IF(COUNTIF($I:$I,A24)>0,"In I","Not in I") -> In I | I24: FWI2539-06134
A25: FWI2539-05455 | B25: Athena ORT | C25: 1176304 | D25: 000007014624 | E25: ATHN | F25: =IF(COUNTIF($I:$I,A25)>0,"In I","Not in I") -> In I | I25: FWI2539-06150
A26: FWI2539-05489 | B26: Athena ORT | C26: 1176304 | D26: 000007014624 | E26: ATHN | F26: =IF(COUNTIF($I:$I,A26)>0,"In I","Not in I") -> In I | I26: FWI2539-06413
A27: FWI2539-05971 | B27: Athena ORT | C27: 1176304 | D27: 000007014624 | E27: ATHN | F27: =IF(COUNTIF($I:$I,A27)>0,"In I","Not in I") -> In I | I27: FWI2539-09242
... A40: FWI2539-09351 | B40: Athena ORT | C40: 1176304 | D40: 000007014673 | E40: ATHN | F40: =IF(COUNTIF($I:$I,A40)>0,"In I","Not in I") -> In I | I40: FWI2540-07734
A41: FWI2539-09568 | B41: Athena ORT | C41: 1176304 | D41: 000007014673 | E41: ATHN | F41: =IF(COUNTIF($I:$I,A41)>0,"In I","Not in I") -> In I
A42: FWI2539-09652 | B42: Athena ORT | C42: 1176304 | D42: 000007014673 | E42: ATHN | F42: =IF(COUNTIF($I:$I,A42)>0,"In I","Not in I") -> In I
A43: FWI2540-04025 | B43: Athena ORT | C43: 1178139 | D43: 000007015026 | E43: ATHN | F43: =IF(COUNTIF($I:$I,A43)>0,"In I","Not in I") -> Not in I
A44: FWI2540-05195 | B44: Athena ORT | C44: 1176304 | D44: 000007015032 | E44: ATHN | F44: =IF(COUNTIF($I:$I,A44)>0,"In I","Not in I") -> Not in I
A45: FWI2540-05202 | B45: Athena ORT | C45: 1176304 | D45: 000007015032 | E45: ATHN | F45: =IF(COUNTIF($I:$I,A45)>0,"In I","Not in I") -> Not in I
A46: FWI2540-05233 | B46: Athena ORT | C46: 1176304 | D46: 000007015032 | E46: ATHN | F46: =IF(COUNTIF($I:$I,A46)>0,"In I","Not in I") -> Not in I
A47: FWI2540-05238 | B47: Athena ORT | C47: 1176304 | D47: 000007015032 | E47: ATHN | F47: =IF(COUNTIF($I:$I,A47)>0,"In I","Not in I") -> Not in I
A48: FWI2540-05239 | B48: Athena ORT | C48: 1176304 | D48: 000007015032 | E48: ATHN | F48: =IF(COUNTIF($I:$I,A48)>0,"In I","Not in I") -> Not in I
A49: FWI2540-05255 | B49: Athena ORT | C49: 1176304 | D49: 000007015032 | E49: ATHN | F49: =IF(COUNTIF($I:$I,A49)>0,"In I","Not in I") -> Not in I
A50: FWI2540-05299 | B50: Athena ORT | C50: 1176304 | D50: 000007015032 | E50: ATHN | F50: =IF(COUNTIF($I:$I,A50)>0,"In I","Not in I") -> Not in I
A51: FWI2540-05396 | B51: Athena ORT | C51: 1176304 | D51: 000007015032 | E51: ATHN | F51: =IF(COUNTIF($I:$I,A51)>0,"In I","Not in I") -> Not in I
A52: FWI2540-05411 | B52: Athena ORT | C52: 1176304 | D52: 000007015032 | E52: ATHN | F52: =IF(COUNTIF($I:$I,A52)>0,"In I","Not in I") -> Not in I
...
